ERROR:pystray._base:An error occurred when calling message handler
Traceback (most recent call last):
  File "E:\long\office-connector\Office-connector\lib\ui.py", line 28, in exit_app
    sys.exit()  # Exit the application
    ^^^^^^^^^^
SystemExit

During handling of the above exception, another exception occurred:

Traceback (most recent call last):
  File "E:\long\office-connector\Office-connector\venv\Lib\site-packages\pystray\_win32.py", line 412, in _dispatcher
    return int(icon._message_handlers.get(
               ^^^^^^^^^^^^^^^^^^^^^^^^^^^
  File "E:\long\office-connector\Office-connector\venv\Lib\site-packages\pystray\_win32.py", line 224, in _on_notify
    descriptors[index - 1](self)
  File "E:\long\office-connector\Office-connector\venv\Lib\site-packages\pystray\_base.py", line 328, in inner
    callback(self)
  File "E:\long\office-connector\Office-connector\venv\Lib\site-packages\pystray\_base.py", line 453, in __call__
    return self._action(icon, self)
           ^^^^^^^^^^^^^^^^^^^^^^^^
  File "E:\long\office-connector\Office-connector\venv\Lib\site-packages\pystray\_base.py", line 548, in wrapper0
    return action()
           ^^^^^^^^
  File "E:\long\office-connector\Office-connector\lib\ui.py", line 34, in exit_app
    sys.exit()
SystemExit
ERROR:pystray._base:An error occurred when calling message handler
Traceback (most recent call last):
  File "E:\long\office-connector\Office-connector\lib\ui.py", line 28, in exit_app
    sys.exit()  # Exit the application
    ^^^^^^^^^^
SystemExit

During handling of the above exception, another exception occurred:

Traceback (most recent call last):
  File "E:\long\office-connector\Office-connector\venv\Lib\site-packages\pystray\_win32.py", line 412, in _dispatcher
    return int(icon._message_handlers.get(
               ^^^^^^^^^^^^^^^^^^^^^^^^^^^
  File "E:\long\office-connector\Office-connector\venv\Lib\site-packages\pystray\_win32.py", line 224, in _on_notify
    descriptors[index - 1](self)
  File "E:\long\office-connector\Office-connector\venv\Lib\site-packages\pystray\_base.py", line 328, in inner
    callback(self)
  File "E:\long\office-connector\Office-connector\venv\Lib\site-packages\pystray\_base.py", line 453, in __call__
    return self._action(icon, self)
           ^^^^^^^^^^^^^^^^^^^^^^^^
  File "E:\long\office-connector\Office-connector\venv\Lib\site-packages\pystray\_base.py", line 548, in wrapper0
    return action()
           ^^^^^^^^
  File "E:\long\office-connector\Office-connector\lib\ui.py", line 34, in exit_app
    sys.exit()
SystemExit
ERROR:pystray._base:An error occurred when calling message handler
Traceback (most recent call last):
  File "E:\long\office-connector\Office-connector\lib\ui.py", line 29, in exit_app
    sys.exit()  # Exit the application
    ^^^^^^^^^^
SystemExit

During handling of the above exception, another exception occurred:

Traceback (most recent call last):
  File "E:\long\office-connector\Office-connector\venv\Lib\site-packages\pystray\_win32.py", line 412, in _dispatcher
    return int(icon._message_handlers.get(
               ^^^^^^^^^^^^^^^^^^^^^^^^^^^
  File "E:\long\office-connector\Office-connector\venv\Lib\site-packages\pystray\_win32.py", line 224, in _on_notify
    descriptors[index - 1](self)
  File "E:\long\office-connector\Office-connector\venv\Lib\site-packages\pystray\_base.py", line 328, in inner
    callback(self)
  File "E:\long\office-connector\Office-connector\venv\Lib\site-packages\pystray\_base.py", line 453, in __call__
    return self._action(icon, self)
           ^^^^^^^^^^^^^^^^^^^^^^^^
  File "E:\long\office-connector\Office-connector\venv\Lib\site-packages\pystray\_base.py", line 548, in wrapper0
    return action()
           ^^^^^^^^
  File "E:\long\office-connector\Office-connector\lib\ui.py", line 35, in exit_app
    sys.exit()
SystemExit
